Workbook

Sheet Legenda
A1: Regra | B1: Tudo que aparece no jogo tem que ser ilustração 100% humana. Ilustração de IA NÃO conta como pronta: está listada como 'Ilustração de IA — refazer'.
A2: Como usar | B2: Na aba Ilustrações, a equipe preenche só as colunas amarelas: Responsável, Status (lista: A fazer / Em andamento / Em revisão / Pronto) e Observações. A aba Resumo conta sozinha.
A3: Prioridade | B3: '1 – Demo (Arco 1)' = precisa para a demo do Arco 1. '2 – Arco 2' e '3 – Arco 3 / final' = arcos seguintes (seguem o GDD v0.03).
A4: Situação atual
A5: Ilustração de IA — refazer | B5: Hoje o jogo usa um sprite gerado por IA (Assets/Sprites/Criaturas: Inspetora.png, Diretor.png, Amelie_sombra.png). Precisa ser redesenhado.
A6: Bloco provisório (cinza) | B6: Cena ou objeto montado com caixas cinzas/coloridas no código, esperando arte.
A7: Placeholder de cor | B7: Animação ou efeito com um desenho provisório (ex.: Luma tingida de uma cor) só para testar.
A8: Sem ilustração | B8: Ainda não existe nenhum desenho (o jogo mostra só texto, brilho ou nada), ou é item previsto no GDD.
A9: Arte humana parcial | B9: Já existe arte humana, mas falta uma pose/variação, ou ela precisa ser conferida.
A11: Já é arte humana (não entra na lista) | B11: Cenários: quarto.psd (Dormitório 1 e fundo do menu), corredor.psd (Corredor 1 e Pesadelo), banheiro.psd, quarto 2.psd (Dormitório 2), corredor 2.psd (térreo), 3° andar.psd. Luma.psb com os 9 quadros do Idle de frente. Textura do chão (floor-material).
A12: Levantado em | B12: 28/09/2026, a partir do projeto Unity (Assets/Sprites, cenas e scripts de montagem) e do GDD v0.03.

Sheet Ilustrações
A1: ID | B1: Categoria | C1: Item | D1: Onde aparece | E1: Situação atual | F1: O que desenhar | G1: Formato de entrega | H1: Prioridade | I1: Responsável | J1: Status | K1: Observações
A2: CR01 | B2: Criaturas | C2: Inspetora — forma verdadeira (andando) | D2: 03_Banheiro (encontro), 06_Dormitorio2, ronda do 2º andar (Corredor 1, Banheiro, Dormitório 2) | E2: Ilustração de IA — refazer | F2: Massa escura de galhos e cabelos, ~2,3 m em cena. Poses: parada, andando, perseguindo, farejando (parada, cabeça baixa), agarrando a Luma (captura). | G2: PSD/PSB em camadas (partes separadas para animar) ou PNG por quadro; fundo transparente; ~1400 px de altura | H2: 1 – Demo (Arco 1) | J2: A fazer | K2: Hoje é Assets/Sprites/Criaturas/Inspetora.png (IA). A sombra na parede da ronda usa este mesmo desenho escurecido.
A3: CR02 | B3: Criaturas | C3: Inspetora — massa que persegue (galhos em camadas) | D3: 02_Corredor1 (fuga), 09_LazyRoom (ninho) | E3: Ilustração de IA — refazer | F3: A massa inteira ocupando o corredor, em 3 camadas soltas (frente, meio, fundo) para ondular. Borda da frente bem definida (é onde ela 'pega'). | G3: PSD com 3 camadas separadas; ~3,6 m de altura em cena | H3: 1 – Demo (Arco 1) | J3: A fazer | K3: Hoje empilha o Inspetora.png (IA). O corredor 2.psd já tem uma massa pintada pela equipe (Camadas 6, 7, 8): dá para seguir aquele estilo.
A4: CR03 | B4: Criaturas | C4: Inspetora — galhos passando (susto da escada) | D4: 02_Corredor1 (Susto_Escada) | E4: Arte humana parcial | F4: Galhos/braços atravessando a escada rapidamente (1 imagem, lateral). | G4: PNG transparente ~512 px | H4: 1 – Demo (Arco 1) | J4: A fazer | K4: Usa a Camada 8 do corredor 2.psd (humana) e cai no Inspetora.png (IA) se ela faltar. Conferir se a camada serve para este susto.
A5: CR04 | B5: Criaturas | C5: Inspetora — reflexo no espelho | D5: 03_Banheiro (Susto_Espelho) | E5: Arte humana parcial | F5: Rosto/silhueta dela refletida no espelho do banheiro, por um instante. | G5: PNG transparente ~512 px | H5: 1 – Demo (Arco 1) | J5: A fazer | K5: Mesmo caso do item acima (Camada 8 do corredor 2.psd ou IA).
A6: CR05 | B6: Criaturas | C6: Inspetora — forma de dia (mulher alta e silenciosa) | D6: Memórias da chegada; aparições diurnas | E6: Sem ilustração | F6: Mulher alta, silenciosa, que apaga as luzes dos dormitórios. | G6: PSD/PSB em camadas (partes separadas para animar) ou PNG por quadro; fundo transparente; ~1400 px de altura | H6: 2 – Arco 2 | J6: A fazer | K6: Previsto no GDD; ainda não está no jogo.
A7: CR06 | B7: Criaturas | C7: Diretor — forma verdadeira | D7: 00_Pesadelo (figura alta ao lado da Amelie); Arco 2: escritório, armazém, dormitório 2 | E7: Ilustração de IA — refazer | F7: Figura escura e volumosa, máscara branca com um único furo, cercado de fichas. Poses: sentado escrevendo, parado ouvindo, procurando, andando. | G7: PSD/PSB em camadas (partes separadas para animar) ou PNG por quadro; fundo transparente; ~1400 px de altura | H7: 1 – Demo (Arco 1) | J7: A fazer | K7: Hoje é Assets/Sprites/Criaturas/Diretor.png (IA), usado no pesadelo. Prioridade 1 pelo pesadelo; as poses de gameplay são do Arco 2.
A8: CR07 | B8: Criaturas | C8: Diretor — forma de dia | D8: Memória da chegada (recebe as irmãs na entrada) | E8: Sem ilustração | F8: Adulto severo e distante na porta do orfanato. | G8: PSD/PSB em camadas (partes separadas para animar) ou PNG por quadro; fundo transparente; ~1400 px de altura | H8: 2 – Arco 2 | J8: A fazer
A9: CR08 | B9: Criaturas | C9: Governanta — forma verdadeira | D9: Arco 3: lavanderia, o Fundo, sala do livro | E9: Sem ilustração | F9: Figura enorme envolta em lençóis, que abraça tudo à volta (opção recomendada no GDD: autofobia). | G9: PSD/PSB em camadas (partes separadas para animar) ou PNG por quadro; fundo transparente; ~1400 px de altura | H9: 3 – Arco 3 / final | J9: A fazer | K9: Fobia do Arco 3 ainda não definida em definitivo.
A10: CR09 | B10: Criaturas | C10: Figuras altas do pesadelo (silhuetas) | D10: 00_Pesadelo | E10: Ilustração de IA — refazer | F10: Duas silhuetas altas, quase invisíveis no escuro, conduzindo a Amelie. Não devem ser identificáveis. | G10: PSD/PSB em camadas (partes separadas para animar) ou PNG por quadro; fundo transparente; ~1400 px de altura | H10: 1 – Demo (Arco 1) | J10: A fazer | K10: Hoje são o Diretor.png e o Inspetora.png (IA) escurecidos. Podem sair dos desenhos novos do Diretor e da Inspetora, mas como silhuetas próprias.
A11: PE01 | B11: Personagens | C11: Amelie — no pesadelo (de costas e virando) | D11: 00_Pesadelo | E11: Arte humana parcial | F11: Amelie andando de costas pelo corredor e, uma vez, virando para trás ao dizer 'Eu volto antes de você...'. | G11: PSD/PSB em camadas (partes separadas para animar) ou PNG por quadro; fundo transparente; ~1400 px de altura | H11: 1 – Demo (Arco 1) | J11: A fazer | K11: Hoje usa a Camada 15 do 3° andar.psd (humana), com o Amelie_sombra.png (IA) de reserva. Falta a pose virando.
A12: PE02 | B12: Personagens | C12: Amelie — nas memórias | D12: Fragmentos: noite da chegada (mão se soltando) e noite da despedida (entregando o urso) | E12: Sem ilustração | F12: Poses curtas e distorcidas: segurando a mão da Luma; colocando o urso nos braços dela. | G12: PSD/PSB em camadas (partes separadas para animar) ou PNG por quadro; fundo transparente; ~1400 px de altura | H12: 2 – Arco 2 | J12: A fazer | K12: Memórias devem ser curtas, visualmente distorcidas e incompletas (GDD).
A13: PE03 | B13: Personagens | C13: Amelie — no Fundo (imóvel, com a página) | D13: Arco 3, final | E13: Sem ilustração | F13: Amelie imóvel ao lado do livro, com a página arrancada nas mãos. Contido e respeitoso, sem violência gráfica. | G13: PSD/PSB em camadas (partes separadas para animar) ou PNG por quadro; fundo transparente; ~1400 px de altura | H13: 3 – Arco 3 / final | J13: A fazer
A14: PE04 | B14: Personagens | C14: Crianças dormindo (dormitório 2) | D14: 06_Dormitorio2 (5 crianças) | E14: Sem ilustração | F14: Crianças nas camas: dormindo, se mexendo (1º aviso) e acordando (2º aviso). | G14: PSD/PSB em camadas (partes separadas para animar) ou PNG por quadro; fundo transparente; ~1400 px de altura | H14: 1 – Demo (Arco 1) | J14: A fazer | K14: O componente SleepingChild não tem desenho. Conferir se o quarto 2.psd já pinta crianças nas camas.
A15: PE05 | B15: Personagens | C15: Outras crianças do orfanato | D15: Arcos 1–2 (sussurros, testemunhos) | E15: Sem ilustração | F15: Crianças comuns do orfanato, de pijama. | G15: PSD/PSB em camadas (partes separadas para animar) ou PNG por quadro; fundo transparente; ~1400 px de altura | H15: 2 – Arco 2 | J15: A fazer | K15: Previsto no GDD.
A16: LU01 | B16: Luma (animações) | C16: Parada — lateral | D16: Todas as cenas | E16: Sem ilustração | F16: Respiração parada em vista lateral (hoje só existe o Idle de frente). | G16: Quadros no Luma.psb, mesmo estilo e tamanho dos 9 quadros do Idle; vista lateral (o jogo espelha para a esquerda) | H16: 1 – Demo (Arco 1) | J16: A fazer | K16: Luma.psb e os 9 quadros do Idle de frente já são arte humana.
A17: LU02 | B17: Luma (animações) | C17: Andar | D17: Todas as cenas | E17: Sem ilustração | F17: Ciclo de caminhada lateral. | G17: Quadros no Luma.psb, mesmo estilo e tamanho dos 9 quadros do Idle; vista lateral (o jogo espelha para a esquerda) | H17: 1 – Demo (Arco 1) | J17: A fazer | K17: Estado 'Walk' ainda não existe no Animator.
A18: LU03 | B18: Luma (animações) | C18: Correr | D18: Todas as cenas | E18: Sem ilustração | F18: Ciclo de corrida lateral (criança, desajeitada). | G18: Quadros no Luma.psb, mesmo estilo e tamanho dos 9 quadros do Idle; vista lateral (o jogo espelha para a esquerda) | H18: 1 – Demo (Arco 1) | J18: A fazer
A19: LU04 | B19: Luma (animações) | C19: Pular | D19: Todas as cenas | E19: Sem ilustração | F19: Impulso, no ar, queda. | G19: Quadros no Luma.psb, mesmo estilo e tamanho dos 9 quadros do Idle; vista lateral (o jogo espelha para a esquerda) | H19: 1 – Demo (Arco 1) | J19: A fazer
A20: LU05 | B20: Luma (animações) | C20: Subir / escalar | D20: Estantes, baú, mesa, beliche | E20: Placeholder de cor | F20: Luma se agarrando e subindo em algo da altura dela. | G20: Quadros no Luma.psb, mesmo estilo e tamanho dos 9 quadros do Idle; vista lateral (o jogo espelha para a esquerda) | H20: 1 – Demo (Arco 1) | J20: A fazer | K20: Hoje é o clipe placeholder azul Luma_Climb.anim.
A21: LU06 | B21: Luma (animações) | C21: Empurrar | D21: Estantes e baú (Dormitório 1, Biblioteca) | E21: Placeholder de cor | F21: Empurrando um móvel pesado. | G21: Quadros no Luma.psb, mesmo estilo e tamanho dos 9 quadros do Idle; vista lateral (o jogo espelha para a esquerda) | H21: 1 – Demo (Arco 1) | J21: A fazer | K21: Placeholder amarelo Luma_Push.anim.
A22: LU07 | B22: Luma (animações) | C22: Puxar | D22: Estantes e baú | E22: Placeholder de cor | F22: Puxando um móvel, andando de costas. | G22: Quadros no Luma.psb, mesmo estilo e tamanho dos 9 quadros do Idle; vista lateral (o jogo espelha para a esquerda) | H22: 1 – Demo (Arco 1) | J22: A fazer | K22: Placeholder laranja Luma_Pull.anim.
A23: LU08 | B23: Luma (animações) | C23: Segurando parada | D23: Estantes e baú | E23: Placeholder de cor | F23: Mãos no móvel, parada. | G23: Quadros no Luma.psb, mesmo estilo e tamanho dos 9 quadros do Idle; vista lateral (o jogo espelha para a esquerda) | H23: 1 – Demo (Arco 1) | J23: A fazer | K23: Placeholder bege Luma_Grab.anim.
A24: LU09 | B24: Luma (animações) | C24: Esconder (entrar/sair) | D24: Embaixo da cama/mesa, cortina, cabine, armário | E24: Placeholder de cor | F24: Entrando e saindo do esconderijo; encolhida escondida (quando o esconderijo não some com o sprite). | G24: Quadros no Luma.psb, mesmo estilo e tamanho dos 9 quadros do Idle; vista lateral (o jogo espelha para a esquerda) | H24: 1 – Demo (Arco 1) | J24: A fazer | K24: Placeholder Luma_Hide.anim.
A25: LU10 | B25: Luma (animações) | C25: Sendo pega / puxada | D25: Captura (todas as criaturas) | E25: Placeholder de cor | F25: Susto e sendo arrastada para fora do quadro. | G25: Quadros no Luma.psb, mesmo estilo e tamanho dos 9 quadros do Idle; vista lateral (o jogo espelha para a esquerda) | H25: 1 – Demo (Arco 1) | J25: A fazer | K25: Placeholder vermelho Luma_Caught.anim.
A26: LU11 | B26: Luma (animações) | C26: Escada (subindo e descendo) | D26: 02_Corredor1 (escadas 3D) | E26: Placeholder de cor | F26: De costas subindo; de costas descendo. | G26: Quadros no Luma.psb, mesmo estilo e tamanho dos 9 quadros do Idle; vista lateral (o jogo espelha para a esquerda) | H26: 1 – Demo (Arco 1) | J26: A fazer | K26: Placeholder verde Luma_Stairs.anim.
A27: LU12 | B27: Luma (animações) | C27: Abraçando o urso | D27: Todas as cenas (tecla F) | E27: Sem ilustração | F27: Parada, abraçando o urso de pelúcia com força. | G27: Quadros no Luma.psb, mesmo estilo e tamanho dos 9 quadros do Idle; vista lateral (o jogo espelha para a esquerda) | H27: 1 – Demo (Arco 1) | J27: A fazer | K27: Mecânica já funciona; estado 'Hug' sem desenho.
A28: LU13 | B28: Luma (animações) | C28: Marca no pulso escurecendo | D28: Todas as cenas | E28: Sem ilustração | F28: Manchinha de tinta no pulso, visível desde o início; versão mais escura para medo alto. | G28: Camada separada no Luma.psb (2 versões da mancha) | H28: 1 – Demo (Arco 1) | J28: A fazer | K28: GDD: detalhe discreto que o jogador percebe sem entender.
A29: LU14 | B29: Luma (animações) | C29: Acordando na cama / deitada | D29: 01_Dormitorio1 (despertar), final do jogo | E29: Sem ilustração | F29: Deitada abraçada ao urso; sentando assustada. | G29: Quadros no Luma.psb, mesmo estilo e tamanho dos 9 quadros do Idle; vista lateral (o jogo espelha para a esquerda) | H29: 1 – Demo (Arco 1) | J29: A fazer
A30: LU15 | B30: Luma (animações) | C30: Pegar / olhar objeto | D30: Pistas e itens | E30: Sem ilustração | F30: Abaixando para pegar; olhando algo na mão. | G30: Quadros no Luma.psb, mesmo estilo e tamanho dos 9 quadros do Idle; vista lateral (o jogo espelha para a esquerda) | H30: 2 – Arco 2 | J30: A fazer | K30: Opcional para a demo.
A31: CE01 | B31: Cenários | C31: 08_Biblioteca | D31: Arco 1 (demo) | E31: Bloco provisório (cinza) | F31: Biblioteca abafada: estantes altas, armário alto (a Luma sobe nele pelo baú), mesa de leitura, baú empurrável, porta para o corredor. | G31: PSD em camadas no padrão dos cenários da equipe (fundo, chão, móveis soltos e da frente em camadas separadas), mesma proporção e estilo do corredor.psd | H31: 1 – Demo (Arco 1) | J31: A fazer | K31: Cena provisória em blocos cinza ('arte pendente').
A32: CE02 | B32: Cenários | C32: 09_LazyRoom (sala de descanso / ninho da Inspetora) | D32: Arco 1 (demo) | E32: Bloco provisório (cinza) | F32: Sofá, poltrona, mesinha, caixa de luz na parede, lâmpada no teto, tigela; o ninho de galhos num canto; porta da sala de estar. | G32: PSD em camadas no padrão dos cenários da equipe (fundo, chão, móveis soltos e da frente em camadas separadas), mesma proporção e estilo do corredor.psd | H32: 1 – Demo (Arco 1) | J32: A fazer | K32: Cena provisória em blocos cinza.
A33: CE03 | B33: Cenários | C33: 10_LivingRoom (sala de estar) | D33: Arco 1 (fim da demo) | E33: Bloco provisório (cinza) | F33: Lareira apagada (com o bilhete F01 em cima), duas poltronas, relógio de pé, janela. | G33: PSD em camadas no padrão dos cenários da equipe (fundo, chão, móveis soltos e da frente em camadas separadas), mesma proporção e estilo do corredor.psd | H33: 1 – Demo (Arco 1) | J33: A fazer | K33: Cena provisória em blocos cinza.
A34: CE04 | B34: Cenários | C34: Porta da biblioteca (Corredor 1) | D34: 02_Corredor1 | E34: Bloco provisório (cinza) | F34: Porta da biblioteca com placa, no fundo do nicho, integrada à pintura do corredor. | G34: Camada nova no corredor.psd | H34: 1 – Demo (Arco 1) | J34: A fazer | K34: Hoje: bloco marrom + texto 'BIBLIOTECA' gerado no código.
A35: CE05 | B35: Cenários | C35: Escada que desce ao térreo (Corredor 1) | D35: 02_Corredor1 | E35: Sem ilustração | F35: Porta/abertura embaixo do lance de subida, com os primeiros degraus descendo para o escuro. | G35: Camada nova no corredor.psd + pintura do poço (degraus, paredes) | H35: 1 – Demo (Arco 1) | J35: A fazer | K35: Hoje os degraus usam pedaços dos degraus pintados da subida como textura.
A36: CE06 | B36: Cenários | C36: Tábuas soltas (Dormitório 2) | D36: 06_Dormitorio2 (2 tábuas) | E36: Bloco provisório (cinza) | F36: Tábuas do piso levemente soltas/levantadas, que o jogador precisa reconhecer. | G36: PNG transparente ~512 px | H36: 1 – Demo (Arco 1) | J36: A fazer | K36: Hoje: blocos marrons finos.
A37: CE07 | B37: Cenários | C37: 07_Escritorio (sala do Diretor) | D37: Arco 2 | E37: Bloco provisório (cinza) | F37: Mesa do Diretor, arquivos de fichas, pilhas de fichas. | G37: PSD em camadas no padrão dos cenários da equipe (fundo, chão, móveis soltos e da frente em camadas separadas), mesma proporção e estilo do corredor.psd | H37: 2 – Arco 2 | J37: A fazer | K37: O GDD cita um esboço do escritório já desenhado: conferir se ele existe fora do projeto.
A38: CE08 | B38: Cenários | C38: 3º andar: armazém, quarto do Diretor, varanda | D38: Arco 2 | E38: Sem ilustração | F38: Um cenário por cômodo, seguindo a planta da equipe. | G38: PSD em camadas no padrão dos cenários da equipe (fundo, chão, móveis soltos e da frente em camadas separadas), mesma proporção e estilo do corredor.psd | H38: 2 – Arco 2 | J38: A fazer | K38: O 3° andar.psd (corredor do 3º andar) já é arte humana.
A39: CE09 | B39: Cenários | C39: Térreo: sala de aula, igreja, refeitório, cozinha, 2º corredor | D39: Arco 2 | E39: Sem ilustração | F39: Um cenário por cômodo, seguindo a planta. | G39: PSD em camadas no padrão dos cenários da equipe (fundo, chão, móveis soltos e da frente em camadas separadas), mesma proporção e estilo do corredor.psd | H39: 2 – Arco 2 | J39: A fazer | K39: O corredor 2.psd (1º corredor do térreo) já é arte humana.
A40: CE10 | B40: Cenários | C40: Sótão (depósito) | D40: Arco 2 (caderno da Amelie) | E40: Sem ilustração | F40: Depósito no sótão, lugar que só as irmãs conheciam. | G40: PSD em camadas no padrão dos cenários da equipe (fundo, chão, móveis soltos e da frente em camadas separadas), mesma proporção e estilo do corredor.psd | H40: 2 – Arco 2 | J40: A fazer
...

Sheet Resumo
A1: Ilustrações do Umbra — resumo
A2: Atualiza sozinho quando a coluna Status da aba Ilustrações muda.
A4: Por categoria | B4: Total | C4: A fazer | D4: Em andamento | E4: Em revisão | F4: Pronto | G4: % pronto
A5: Criaturas | B5: =COUNTIF('Ilustrações'!$B$2:$B$72,$A5) | C5: =COUNTIFS('Ilustrações'!$B$2:$B$72,$A5,'Ilustrações'!$J$2:$J$72,"A fazer") | D5: =COUNTIFS('Ilustrações'!$B$2:$B$72,$A5,'Ilustrações'!$J$2:$J$72,"Em andamento") | E5: =COUNTIFS('Ilustrações'!$B$2:$B$72,$A5,'Ilustrações'!$J$2:$J$72,"Em revisão") | F5: =COUNTIFS('Ilustrações'!$B$2:$B$72,$A5,'Ilustrações'!$J$2:$J$72,"Pronto") | G5: =IF(B5=0,0,F5/B5)
A6: Personagens | B6: =COUNTIF('Ilustrações'!$B$2:$B$72,$A6) | C6: =COUNTIFS('Ilustrações'!$B$2:$B$72,$A6,'Ilustrações'!$J$2:$J$72,"A fazer") | D6: =COUNTIFS('Ilustrações'!$B$2:$B$72,$A6,'Ilustrações'!$J$2:$J$72,"Em andamento") | E6: =COUNTIFS('Ilustrações'!$B$2:$B$72,$A6,'Ilustrações'!$J$2:$J$72,"Em revisão") | F6: =COUNTIFS('Ilustrações'!$B$2:$B$72,$A6,'Ilustrações'!$J$2:$J$72,"Pronto") | G6: =IF(B6=0,0,F6/B6)
A7: Luma (animações) | B7: =COUNTIF('Ilustrações'!$B$2:$B$72,$A7) | C7: =COUNTIFS('Ilustrações'!$B$2:$B$72,$A7,'Ilustrações'!$J$2:$J$72,"A fazer") | D7: =COUNTIFS('Ilustrações'!$B$2:$B$72,$A7,'Ilustrações'!$J$2:$J$72,"Em andamento") | E7: =COUNTIFS('Ilustrações'!$B$2:$B$72,$A7,'Ilustrações'!$J$2:$J$72,"Em revisão") | F7: =COUNTIFS('Ilustrações'!$B$2:$B$72,$A7,'Ilustrações'!$J$2:$J$72,"Pronto") | G7: =IF(B7=0,0,F7/B7)
A8: Cenários | B8: =COUNTIF('Ilustrações'!$B$2:$B$72,$A8) | C8: =COUNTIFS('Ilustrações'!$B$2:$B$72,$A8,'Ilustrações'!$J$2:$J$72,"A fazer") | D8: =COUNTIFS('Ilustrações'!$B$2:$B$72,$A8,'Ilustrações'!$J$2:$J$72,"Em andamento") | E8: =COUNTIFS('Ilustrações'!$B$2:$B$72,$A8,'Ilustrações'!$J$2:$J$72,"Em revisão") | F8: =COUNTIFS('Ilustrações'!$B$2:$B$72,$A8,'Ilustrações'!$J$2:$J$72,"Pronto") | G8: =IF(B8=0,0,F8/B8)
A9: Objetos e itens | B9: =COUNTIF('Ilustrações'!$B$2:$B$72,$A9) | C9: =COUNTIFS('Ilustrações'!$B$2:$B$72,$A9,'Ilustrações'!$J$2:$J$72,"A fazer") | D9: =COUNTIFS('Ilustrações'!$B$2:$B$72,$A9,'Ilustrações'!$J$2:$J$72,"Em andamento") | E9: =COUNTIFS('Ilustrações'!$B$2:$B$72,$A9,'Ilustrações'!$J$2:$J$72,"Em revisão") | F9: =COUNTIFS('Ilustrações'!$B$2:$B$72,$A9,'Ilustrações'!$J$2:$J$72,"Pronto") | G9: =IF(B9=0,0,F9/B9)
A10: Pistas (tela de leitura) | B10: =COUNTIF('Ilustrações'!$B$2:$B$72,$A10) | C10: =COUNTIFS('Ilustrações'!$B$2:$B$72,$A10,'Ilustrações'!$J$2:$J$72,"A fazer") | D10: =COUNTIFS('Ilustrações'!$B$2:$B$72,$A10,'Ilustrações'!$J$2:$J$72,"Em andamento") | E10: =COUNTIFS('Ilustrações'!$B$2:$B$72,$A10,'Ilustrações'!$J$2:$J$72,"Em revisão") | F10: =COUNTIFS('Ilustrações'!$B$2:$B$72,$A10,'Ilustrações'!$J$2:$J$72,"Pronto") | G10: =IF(B10=0,0,F10/B10)
A11: Interface | B11: =COUNTIF('Ilustrações'!$B$2:$B$72,$A11) | C11: =COUNTIFS('Ilustrações'!$B$2:$B$72,$A11,'Ilustrações'!$J$2:$J$72,"A fazer") | D11: =COUNTIFS('Ilustrações'!$B$2:$B$72,$A11,'Ilustrações'!$J$2:$J$72,"Em andamento") | E11: =COUNTIFS('Ilustrações'!$B$2:$B$72,$A11,'Ilustrações'!$J$2:$J$72,"Em revisão") | F11: =COUNTIFS('Ilustrações'!$B$2:$B$72,$A11,'Ilustrações'!$J$2:$J$72,"Pronto") | G11: =IF(B11=0,0,F11/B11)
A12: Total | B12: =SUM(B5:B11) | C12: =SUM(C5:C11) | D12: =SUM(D5:D11) | E12: =SUM(E5:E11) | F12: =SUM(F5:F11) | G12: =IF(B12=0,0,F12/B12)
A14: Por prioridade | B14: Total | C14: Pronto | D14: Falta
A15: 1 – Demo (Arco 1) | B15: =COUNTIF('Ilustrações'!$H$2:$H$72,$A15) | C15: =COUNTIFS('Ilustrações'!$H$2:$H$72,$A15,'Ilustrações'!$J$2:$J$72,"Pronto") | D15: =B15-C15
A16: 2 – Arco 2 | B16: =COUNTIF('Ilustrações'!$H$2:$H$72,$A16) | C16: =COUNTIFS('Ilustrações'!$H$2:$H$72,$A16,'Ilustrações'!$J$2:$J$72,"Pronto") | D16: =B16-C16
A17: 3 – Arco 3 / final | B17: =COUNTIF('Ilustrações'!$H$2:$H$72,$A17) | C17: =COUNTIFS('Ilustrações'!$H$2:$H$72,$A17,'Ilustrações'!$J$2:$J$72,"Pronto") | D17: =B17-C17
A19: Por situação atual | B19: Itens
A20: Ilustração de IA — refazer | B20: =COUNTIF('Ilustrações'!$E$2:$E$72,$A20)
A21: Bloco provisório (cinza) | B21: =COUNTIF('Ilustrações'!$E$2:$E$72,$A21)
A22: Placeholder de cor | B22: =COUNTIF('Ilustrações'!$E$2:$E$72,$A22)
A23: Sem ilustração | B23: =COUNTIF('Ilustrações'!$E$2:$E$72,$A23)
A24: Arte humana parcial | B24: =COUNTIF('Ilustrações'!$E$2:$E$72,$A24)
